{
 "cells": [
  {
   "cell_type": "markdown",
   "id": "147cd53b",
   "metadata": {},
   "source": [
    "- beers per user : 373 seconds\n",
    "- std : 66 seconds\n",
    "- explorer score per user : 0.3 seconds per user\n",
    "- adventurer score per user : 0.09 s per user"
   ]
  },
  {
   "cell_type": "code",
   "execution_count": 1,
   "id": "81425332",
   "metadata": {},
   "outputs": [],
   "source": [
    "import pandas as pd\n",
    "import time\n",
    "\n",
    "import categories as cat"
   ]
  },
  {
   "cell_type": "code",
   "execution_count": 2,
   "id": "303beab3",
   "metadata": {},
   "outputs": [],
   "source": [
    "ratings_parquets_path = 'RefinedData/BeerAdvocate//ratings.parquet'\n",
    "beers_parquet_path = \"RefinedData/BeerAdvocate/beers.parquet/\"\n",
    "users_parquet_path = \"RefinedData/BeerAdvocate/users.parquet/\""
   ]
  },
  {
   "cell_type": "code",
   "execution_count": 3,
   "id": "b2ff89a0",
   "metadata": {},
   "outputs": [
    {
     "name": "stdout",
     "output_type": "stream",
     "text": [
      "ratings loaded\n",
      "beers loaded\n",
      "users loaded\n",
      "ratings dated ( 269.9464454650879 )\n",
      "Unexpected exception formatting exception. Falling back to standard exception\n"
     ]
    },
    {
     "name": "stderr",
     "output_type": "stream",
     "text": [
      "Traceback (most recent call last):\n",
      "  File \"c:\\Users\\avern\\AppData\\Local\\Programs\\Python\\Python39\\lib\\site-packages\\IPython\\core\\interactiveshell.py\", line 3369, in run_code\n",
      "    exec(code_obj, self.user_global_ns, self.user_ns)\n",
      "  File \"C:\\Users\\avern\\AppData\\Local\\Temp\\ipykernel_15112\\4279212998.py\", line 2, in <cell line: 2>\n",
      "    categorization = cat.Categorization(ratings_parquets_path, beers_parquet_path, users_parquet_path)\n",
      "  File \"c:\\Users\\avern\\Documents\\GitHub\\ada-2022-project-analytea\\categories.py\", line 60, in __init__\n",
      "    self.beers_per_users = self._beers_per_user()\n",
      "  File \"c:\\Users\\avern\\Documents\\GitHub\\ada-2022-project-analytea\\categories.py\", line 128, in _beers_per_user\n",
      "    for _, row in self.ratings_ddf.iterrows():\n",
      "  File \"c:\\Users\\avern\\AppData\\Local\\Programs\\Python\\Python39\\lib\\site-packages\\pandas\\core\\frame.py\", line 1324, in iterrows\n",
      "    s = klass(v, index=columns, name=k)\n",
      "  File \"c:\\Users\\avern\\AppData\\Local\\Programs\\Python\\Python39\\lib\\site-packages\\pandas\\core\\series.py\", line 455, in __init__\n",
      "    data = SingleBlockManager.from_array(data, index)\n",
      "  File \"c:\\Users\\avern\\AppData\\Local\\Programs\\Python\\Python39\\lib\\site-packages\\pandas\\core\\internals\\managers.py\", line 1737, in from_array\n",
      "    return cls(block, index)\n",
      "  File \"c:\\Users\\avern\\AppData\\Local\\Programs\\Python\\Python39\\lib\\site-packages\\pandas\\core\\internals\\managers.py\", line 1720, in __init__\n",
      "    self.blocks = (block,)\n",
      "KeyboardInterrupt\n",
      "\n",
      "During handling of the above exception, another exception occurred:\n",
      "\n",
      "Traceback (most recent call last):\n",
      "  File \"c:\\Users\\avern\\AppData\\Local\\Programs\\Python\\Python39\\lib\\site-packages\\IPython\\core\\interactiveshell.py\", line 1982, in showtraceback\n",
      "    stb = self.InteractiveTB.structured_traceback(\n",
      "  File \"c:\\Users\\avern\\AppData\\Local\\Programs\\Python\\Python39\\lib\\site-packages\\IPython\\core\\ultratb.py\", line 1118, in structured_traceback\n",
      "    return FormattedTB.structured_traceback(\n",
      "  File \"c:\\Users\\avern\\AppData\\Local\\Programs\\Python\\Python39\\lib\\site-packages\\IPython\\core\\ultratb.py\", line 1012, in structured_traceback\n",
      "    return VerboseTB.structured_traceback(\n",
      "  File \"c:\\Users\\avern\\AppData\\Local\\Programs\\Python\\Python39\\lib\\site-packages\\IPython\\core\\ultratb.py\", line 865, in structured_traceback\n",
      "    formatted_exception = self.format_exception_as_a_whole(etype, evalue, etb, number_of_lines_of_context,\n",
      "  File \"c:\\Users\\avern\\AppData\\Local\\Programs\\Python\\Python39\\lib\\site-packages\\IPython\\core\\ultratb.py\", line 799, in format_exception_as_a_whole\n",
      "    self.get_records(etb, number_of_lines_of_context, tb_offset) if etb else []\n",
      "  File \"c:\\Users\\avern\\AppData\\Local\\Programs\\Python\\Python39\\lib\\site-packages\\IPython\\core\\ultratb.py\", line 845, in get_records\n",
      "    style = stack_data.style_with_executing_node(style, \"bg:ansiyellow\")\n",
      "  File \"c:\\Users\\avern\\AppData\\Local\\Programs\\Python\\Python39\\lib\\site-packages\\stack_data\\core.py\", line 424, in style_with_executing_node\n",
      "    class NewStyle(style):\n",
      "  File \"c:\\Users\\avern\\AppData\\Local\\Programs\\Python\\Python39\\lib\\site-packages\\pygments\\style.py\", line 91, in __new__\n",
      "    ndef[4] = colorformat(styledef[3:])\n",
      "  File \"c:\\Users\\avern\\AppData\\Local\\Programs\\Python\\Python39\\lib\\site-packages\\pygments\\style.py\", line 58, in colorformat\n",
      "    assert False, \"wrong color format %r\" % text\n",
      "AssertionError: wrong color format 'ansiyellow'\n"
     ]
    }
   ],
   "source": [
    "t = time.time()\n",
    "categorization = cat.Categorization(ratings_parquets_path, beers_parquet_path, users_parquet_path)\n",
    "print(\"run time :\",time.time()-t)"
   ]
  },
  {
   "cell_type": "code",
   "execution_count": null,
   "id": "5be34a61",
   "metadata": {},
   "outputs": [
    {
     "name": "stdout",
     "output_type": "stream",
     "text": [
      "Unexpected exception formatting exception. Falling back to standard exception\n"
     ]
    },
    {
     "name": "stderr",
     "output_type": "stream",
     "text": [
      "Traceback (most recent call last):\n",
      "  File \"c:\\Users\\avern\\AppData\\Local\\Programs\\Python\\Python39\\lib\\site-packages\\IPython\\core\\interactiveshell.py\", line 3369, in run_code\n",
      "    exec(code_obj, self.user_global_ns, self.user_ns)\n",
      "  File \"C:\\Users\\avern\\AppData\\Local\\Temp\\ipykernel_17940\\494683909.py\", line 1, in <cell line: 1>\n",
      "    categorization.compute_all_scores().head()\n",
      "NameError: name 'categorization' is not defined\n",
      "\n",
      "During handling of the above exception, another exception occurred:\n",
      "\n",
      "Traceback (most recent call last):\n",
      "  File \"c:\\Users\\avern\\AppData\\Local\\Programs\\Python\\Python39\\lib\\site-packages\\IPython\\core\\interactiveshell.py\", line 1982, in showtraceback\n",
      "    stb = self.InteractiveTB.structured_traceback(\n",
      "  File \"c:\\Users\\avern\\AppData\\Local\\Programs\\Python\\Python39\\lib\\site-packages\\IPython\\core\\ultratb.py\", line 1118, in structured_traceback\n",
      "    return FormattedTB.structured_traceback(\n",
      "  File \"c:\\Users\\avern\\AppData\\Local\\Programs\\Python\\Python39\\lib\\site-packages\\IPython\\core\\ultratb.py\", line 1012, in structured_traceback\n",
      "    return VerboseTB.structured_traceback(\n",
      "  File \"c:\\Users\\avern\\AppData\\Local\\Programs\\Python\\Python39\\lib\\site-packages\\IPython\\core\\ultratb.py\", line 865, in structured_traceback\n",
      "    formatted_exception = self.format_exception_as_a_whole(etype, evalue, etb, number_of_lines_of_context,\n",
      "  File \"c:\\Users\\avern\\AppData\\Local\\Programs\\Python\\Python39\\lib\\site-packages\\IPython\\core\\ultratb.py\", line 799, in format_exception_as_a_whole\n",
      "    self.get_records(etb, number_of_lines_of_context, tb_offset) if etb else []\n",
      "  File \"c:\\Users\\avern\\AppData\\Local\\Programs\\Python\\Python39\\lib\\site-packages\\IPython\\core\\ultratb.py\", line 845, in get_records\n",
      "    style = stack_data.style_with_executing_node(style, \"bg:ansiyellow\")\n",
      "  File \"c:\\Users\\avern\\AppData\\Local\\Programs\\Python\\Python39\\lib\\site-packages\\stack_data\\core.py\", line 424, in style_with_executing_node\n",
      "    class NewStyle(style):\n",
      "  File \"c:\\Users\\avern\\AppData\\Local\\Programs\\Python\\Python39\\lib\\site-packages\\pygments\\style.py\", line 91, in __new__\n",
      "    ndef[4] = colorformat(styledef[3:])\n",
      "  File \"c:\\Users\\avern\\AppData\\Local\\Programs\\Python\\Python39\\lib\\site-packages\\pygments\\style.py\", line 58, in colorformat\n",
      "    assert False, \"wrong color format %r\" % text\n",
      "AssertionError: wrong color format 'ansiyellow'\n"
     ]
    }
   ],
   "source": [
    "categorization.compute_all_scores().head()"
   ]
  },
  {
   "cell_type": "code",
   "execution_count": null,
   "id": "42b3976f",
   "metadata": {},
   "outputs": [
    {
     "name": "stdout",
     "output_type": "stream",
     "text": [
      "Unexpected exception formatting exception. Falling back to standard exception\n"
     ]
    },
    {
     "name": "stderr",
     "output_type": "stream",
     "text": [
      "Traceback (most recent call last):\n",
      "  File \"c:\\Users\\avern\\AppData\\Local\\Programs\\Python\\Python39\\lib\\site-packages\\IPython\\core\\interactiveshell.py\", line 3369, in run_code\n",
      "    exec(code_obj, self.user_global_ns, self.user_ns)\n",
      "  File \"C:\\Users\\avern\\AppData\\Local\\Temp\\ipykernel_17940\\1111922121.py\", line 1, in <cell line: 1>\n",
      "    categorization.users_ddf.dtypes\n",
      "NameError: name 'categorization' is not defined\n",
      "\n",
      "During handling of the above exception, another exception occurred:\n",
      "\n",
      "Traceback (most recent call last):\n",
      "  File \"c:\\Users\\avern\\AppData\\Local\\Programs\\Python\\Python39\\lib\\site-packages\\IPython\\core\\interactiveshell.py\", line 1982, in showtraceback\n",
      "    stb = self.InteractiveTB.structured_traceback(\n",
      "  File \"c:\\Users\\avern\\AppData\\Local\\Programs\\Python\\Python39\\lib\\site-packages\\IPython\\core\\ultratb.py\", line 1118, in structured_traceback\n",
      "    return FormattedTB.structured_traceback(\n",
      "  File \"c:\\Users\\avern\\AppData\\Local\\Programs\\Python\\Python39\\lib\\site-packages\\IPython\\core\\ultratb.py\", line 1012, in structured_traceback\n",
      "    return VerboseTB.structured_traceback(\n",
      "  File \"c:\\Users\\avern\\AppData\\Local\\Programs\\Python\\Python39\\lib\\site-packages\\IPython\\core\\ultratb.py\", line 865, in structured_traceback\n",
      "    formatted_exception = self.format_exception_as_a_whole(etype, evalue, etb, number_of_lines_of_context,\n",
      "  File \"c:\\Users\\avern\\AppData\\Local\\Programs\\Python\\Python39\\lib\\site-packages\\IPython\\core\\ultratb.py\", line 799, in format_exception_as_a_whole\n",
      "    self.get_records(etb, number_of_lines_of_context, tb_offset) if etb else []\n",
      "  File \"c:\\Users\\avern\\AppData\\Local\\Programs\\Python\\Python39\\lib\\site-packages\\IPython\\core\\ultratb.py\", line 845, in get_records\n",
      "    style = stack_data.style_with_executing_node(style, \"bg:ansiyellow\")\n",
      "  File \"c:\\Users\\avern\\AppData\\Local\\Programs\\Python\\Python39\\lib\\site-packages\\stack_data\\core.py\", line 424, in style_with_executing_node\n",
      "    class NewStyle(style):\n",
      "  File \"c:\\Users\\avern\\AppData\\Local\\Programs\\Python\\Python39\\lib\\site-packages\\pygments\\style.py\", line 91, in __new__\n",
      "    ndef[4] = colorformat(styledef[3:])\n",
      "  File \"c:\\Users\\avern\\AppData\\Local\\Programs\\Python\\Python39\\lib\\site-packages\\pygments\\style.py\", line 58, in colorformat\n",
      "    assert False, \"wrong color format %r\" % text\n",
      "AssertionError: wrong color format 'ansiyellow'\n"
     ]
    }
   ],
   "source": [
    "categorization.users_ddf.dtypes\n",
    "categorization.users_ddf['location']=categorization.users_ddf['location'].astype('string')\n",
    "categorization.users_ddf['country']=categorization.users_ddf['country'].astype('string')"
   ]
  },
  {
   "cell_type": "code",
   "execution_count": null,
   "id": "b2a6df23",
   "metadata": {},
   "outputs": [
    {
     "name": "stdout",
     "output_type": "stream",
     "text": [
      "Unexpected exception formatting exception. Falling back to standard exception\n"
     ]
    },
    {
     "name": "stderr",
     "output_type": "stream",
     "text": [
      "Traceback (most recent call last):\n",
      "  File \"c:\\Users\\avern\\AppData\\Local\\Programs\\Python\\Python39\\lib\\site-packages\\IPython\\core\\interactiveshell.py\", line 3369, in run_code\n",
      "    exec(code_obj, self.user_global_ns, self.user_ns)\n",
      "  File \"C:\\Users\\avern\\AppData\\Local\\Temp\\ipykernel_17940\\2575310400.py\", line 3, in <cell line: 3>\n",
      "    categorization.users_ddf.to_parquet(ing.build_path(folderind=\"ba\", filename=\"users\", ext=\".parquet\", basepath=\"RefinedData\"))\n",
      "NameError: name 'categorization' is not defined\n",
      "\n",
      "During handling of the above exception, another exception occurred:\n",
      "\n",
      "Traceback (most recent call last):\n",
      "  File \"c:\\Users\\avern\\AppData\\Local\\Programs\\Python\\Python39\\lib\\site-packages\\IPython\\core\\interactiveshell.py\", line 1982, in showtraceback\n",
      "    stb = self.InteractiveTB.structured_traceback(\n",
      "  File \"c:\\Users\\avern\\AppData\\Local\\Programs\\Python\\Python39\\lib\\site-packages\\IPython\\core\\ultratb.py\", line 1118, in structured_traceback\n",
      "    return FormattedTB.structured_traceback(\n",
      "  File \"c:\\Users\\avern\\AppData\\Local\\Programs\\Python\\Python39\\lib\\site-packages\\IPython\\core\\ultratb.py\", line 1012, in structured_traceback\n",
      "    return VerboseTB.structured_traceback(\n",
      "  File \"c:\\Users\\avern\\AppData\\Local\\Programs\\Python\\Python39\\lib\\site-packages\\IPython\\core\\ultratb.py\", line 865, in structured_traceback\n",
      "    formatted_exception = self.format_exception_as_a_whole(etype, evalue, etb, number_of_lines_of_context,\n",
      "  File \"c:\\Users\\avern\\AppData\\Local\\Programs\\Python\\Python39\\lib\\site-packages\\IPython\\core\\ultratb.py\", line 799, in format_exception_as_a_whole\n",
      "    self.get_records(etb, number_of_lines_of_context, tb_offset) if etb else []\n",
      "  File \"c:\\Users\\avern\\AppData\\Local\\Programs\\Python\\Python39\\lib\\site-packages\\IPython\\core\\ultratb.py\", line 845, in get_records\n",
      "    style = stack_data.style_with_executing_node(style, \"bg:ansiyellow\")\n",
      "  File \"c:\\Users\\avern\\AppData\\Local\\Programs\\Python\\Python39\\lib\\site-packages\\stack_data\\core.py\", line 424, in style_with_executing_node\n",
      "    class NewStyle(style):\n",
      "  File \"c:\\Users\\avern\\AppData\\Local\\Programs\\Python\\Python39\\lib\\site-packages\\pygments\\style.py\", line 91, in __new__\n",
      "    ndef[4] = colorformat(styledef[3:])\n",
      "  File \"c:\\Users\\avern\\AppData\\Local\\Programs\\Python\\Python39\\lib\\site-packages\\pygments\\style.py\", line 58, in colorformat\n",
      "    assert False, \"wrong color format %r\" % text\n",
      "AssertionError: wrong color format 'ansiyellow'\n"
     ]
    }
   ],
   "source": [
    "import ingestion as ing\n",
    "\n",
    "categorization.users_ddf.to_parquet(ing.build_path(folderind=\"ba\", filename=\"users\", ext=\".parquet\", basepath=\"RefinedData\"))"
   ]
  },
  {
   "cell_type": "code",
   "execution_count": null,
   "id": "49ab9a8e",
   "metadata": {},
   "outputs": [
    {
     "data": {
      "text/plain": [
       "n_ratings             int32\n",
       "n_reviews             int32\n",
       "uid                  object\n",
       "username             object\n",
       "joined       datetime64[ns]\n",
       "location             string\n",
       "country              string\n",
       "cfm_score           float64\n",
       "exp_score           float64\n",
       "xpl_score             Int64\n",
       "adv_score             Int64\n",
       "is_cfm                int32\n",
       "is_exp                int32\n",
       "is_xpl                int32\n",
       "is_adv                int32\n",
       "dtype: object"
      ]
     },
     "execution_count": 7,
     "metadata": {},
     "output_type": "execute_result"
    }
   ],
   "source": [
    "users_ddf = pd.read_parquet(users_parquet_path)\n",
    "users_ddf.dtypes\n"
   ]
  },
  {
   "cell_type": "code",
   "execution_count": null,
   "id": "fd8dbf95",
   "metadata": {},
   "outputs": [],
   "source": []
  },
  {
   "cell_type": "code",
   "execution_count": null,
   "id": "1958cbc6",
   "metadata": {},
   "outputs": [
    {
     "name": "stdout",
     "output_type": "stream",
     "text": [
      "Unexpected exception formatting exception. Falling back to standard exception\n"
     ]
    },
    {
     "name": "stderr",
     "output_type": "stream",
     "text": [
      "Traceback (most recent call last):\n",
      "  File \"c:\\Users\\avern\\AppData\\Local\\Programs\\Python\\Python39\\lib\\site-packages\\IPython\\core\\interactiveshell.py\", line 3369, in run_code\n",
      "    exec(code_obj, self.user_global_ns, self.user_ns)\n",
      "  File \"C:\\Users\\avern\\AppData\\Local\\Temp\\ipykernel_17940\\3551303339.py\", line 1, in <cell line: 1>\n",
      "    categorization.get_users_head()\n",
      "NameError: name 'categorization' is not defined\n",
      "\n",
      "During handling of the above exception, another exception occurred:\n",
      "\n",
      "Traceback (most recent call last):\n",
      "  File \"c:\\Users\\avern\\AppData\\Local\\Programs\\Python\\Python39\\lib\\site-packages\\IPython\\core\\interactiveshell.py\", line 1982, in showtraceback\n",
      "    stb = self.InteractiveTB.structured_traceback(\n",
      "  File \"c:\\Users\\avern\\AppData\\Local\\Programs\\Python\\Python39\\lib\\site-packages\\IPython\\core\\ultratb.py\", line 1118, in structured_traceback\n",
      "    return FormattedTB.structured_traceback(\n",
      "  File \"c:\\Users\\avern\\AppData\\Local\\Programs\\Python\\Python39\\lib\\site-packages\\IPython\\core\\ultratb.py\", line 1012, in structured_traceback\n",
      "    return VerboseTB.structured_traceback(\n",
      "  File \"c:\\Users\\avern\\AppData\\Local\\Programs\\Python\\Python39\\lib\\site-packages\\IPython\\core\\ultratb.py\", line 865, in structured_traceback\n",
      "    formatted_exception = self.format_exception_as_a_whole(etype, evalue, etb, number_of_lines_of_context,\n",
      "  File \"c:\\Users\\avern\\AppData\\Local\\Programs\\Python\\Python39\\lib\\site-packages\\IPython\\core\\ultratb.py\", line 799, in format_exception_as_a_whole\n",
      "    self.get_records(etb, number_of_lines_of_context, tb_offset) if etb else []\n",
      "  File \"c:\\Users\\avern\\AppData\\Local\\Programs\\Python\\Python39\\lib\\site-packages\\IPython\\core\\ultratb.py\", line 845, in get_records\n",
      "    style = stack_data.style_with_executing_node(style, \"bg:ansiyellow\")\n",
      "  File \"c:\\Users\\avern\\AppData\\Local\\Programs\\Python\\Python39\\lib\\site-packages\\stack_data\\core.py\", line 424, in style_with_executing_node\n",
      "    class NewStyle(style):\n",
      "  File \"c:\\Users\\avern\\AppData\\Local\\Programs\\Python\\Python39\\lib\\site-packages\\pygments\\style.py\", line 91, in __new__\n",
      "    ndef[4] = colorformat(styledef[3:])\n",
      "  File \"c:\\Users\\avern\\AppData\\Local\\Programs\\Python\\Python39\\lib\\site-packages\\pygments\\style.py\", line 58, in colorformat\n",
      "    assert False, \"wrong color format %r\" % text\n",
      "AssertionError: wrong color format 'ansiyellow'\n"
     ]
    }
   ],
   "source": [
    "categorization.get_users_head()"
   ]
  },
  {
   "cell_type": "code",
   "execution_count": null,
   "id": "df0e1e24",
   "metadata": {},
   "outputs": [
    {
     "name": "stdout",
     "output_type": "stream",
     "text": [
      "Unexpected exception formatting exception. Falling back to standard exception\n"
     ]
    },
    {
     "name": "stderr",
     "output_type": "stream",
     "text": [
      "Traceback (most recent call last):\n",
      "  File \"c:\\Users\\avern\\AppData\\Local\\Programs\\Python\\Python39\\lib\\site-packages\\IPython\\core\\interactiveshell.py\", line 3369, in run_code\n",
      "    exec(code_obj, self.user_global_ns, self.user_ns)\n",
      "  File \"C:\\Users\\avern\\AppData\\Local\\Temp\\ipykernel_17940\\3702011375.py\", line 1, in <cell line: 1>\n",
      "    categorization.get_beers_head()\n",
      "NameError: name 'categorization' is not defined\n",
      "\n",
      "During handling of the above exception, another exception occurred:\n",
      "\n",
      "Traceback (most recent call last):\n",
      "  File \"c:\\Users\\avern\\AppData\\Local\\Programs\\Python\\Python39\\lib\\site-packages\\IPython\\core\\interactiveshell.py\", line 1982, in showtraceback\n",
      "    stb = self.InteractiveTB.structured_traceback(\n",
      "  File \"c:\\Users\\avern\\AppData\\Local\\Programs\\Python\\Python39\\lib\\site-packages\\IPython\\core\\ultratb.py\", line 1118, in structured_traceback\n",
      "    return FormattedTB.structured_traceback(\n",
      "  File \"c:\\Users\\avern\\AppData\\Local\\Programs\\Python\\Python39\\lib\\site-packages\\IPython\\core\\ultratb.py\", line 1012, in structured_traceback\n",
      "    return VerboseTB.structured_traceback(\n",
      "  File \"c:\\Users\\avern\\AppData\\Local\\Programs\\Python\\Python39\\lib\\site-packages\\IPython\\core\\ultratb.py\", line 865, in structured_traceback\n",
      "    formatted_exception = self.format_exception_as_a_whole(etype, evalue, etb, number_of_lines_of_context,\n",
      "  File \"c:\\Users\\avern\\AppData\\Local\\Programs\\Python\\Python39\\lib\\site-packages\\IPython\\core\\ultratb.py\", line 799, in format_exception_as_a_whole\n",
      "    self.get_records(etb, number_of_lines_of_context, tb_offset) if etb else []\n",
      "  File \"c:\\Users\\avern\\AppData\\Local\\Programs\\Python\\Python39\\lib\\site-packages\\IPython\\core\\ultratb.py\", line 845, in get_records\n",
      "    style = stack_data.style_with_executing_node(style, \"bg:ansiyellow\")\n",
      "  File \"c:\\Users\\avern\\AppData\\Local\\Programs\\Python\\Python39\\lib\\site-packages\\stack_data\\core.py\", line 424, in style_with_executing_node\n",
      "    class NewStyle(style):\n",
      "  File \"c:\\Users\\avern\\AppData\\Local\\Programs\\Python\\Python39\\lib\\site-packages\\pygments\\style.py\", line 91, in __new__\n",
      "    ndef[4] = colorformat(styledef[3:])\n",
      "  File \"c:\\Users\\avern\\AppData\\Local\\Programs\\Python\\Python39\\lib\\site-packages\\pygments\\style.py\", line 58, in colorformat\n",
      "    assert False, \"wrong color format %r\" % text\n",
      "AssertionError: wrong color format 'ansiyellow'\n"
     ]
    }
   ],
   "source": [
    "categorization.get_beers_head()"
   ]
  },
  {
   "cell_type": "code",
   "execution_count": null,
   "id": "83164a25",
   "metadata": {},
   "outputs": [
    {
     "name": "stdout",
     "output_type": "stream",
     "text": [
      "Unexpected exception formatting exception. Falling back to standard exception\n"
     ]
    },
    {
     "name": "stderr",
     "output_type": "stream",
     "text": [
      "Traceback (most recent call last):\n",
      "  File \"c:\\Users\\avern\\AppData\\Local\\Programs\\Python\\Python39\\lib\\site-packages\\IPython\\core\\interactiveshell.py\", line 3369, in run_code\n",
      "    exec(code_obj, self.user_global_ns, self.user_ns)\n",
      "  File \"C:\\Users\\avern\\AppData\\Local\\Temp\\ipykernel_17940\\3040348117.py\", line 1, in <cell line: 1>\n",
      "    user_ids = categorization.get_userIds_list()\n",
      "NameError: name 'categorization' is not defined\n",
      "\n",
      "During handling of the above exception, another exception occurred:\n",
      "\n",
      "Traceback (most recent call last):\n",
      "  File \"c:\\Users\\avern\\AppData\\Local\\Programs\\Python\\Python39\\lib\\site-packages\\IPython\\core\\interactiveshell.py\", line 1982, in showtraceback\n",
      "    stb = self.InteractiveTB.structured_traceback(\n",
      "  File \"c:\\Users\\avern\\AppData\\Local\\Programs\\Python\\Python39\\lib\\site-packages\\IPython\\core\\ultratb.py\", line 1118, in structured_traceback\n",
      "    return FormattedTB.structured_traceback(\n",
      "  File \"c:\\Users\\avern\\AppData\\Local\\Programs\\Python\\Python39\\lib\\site-packages\\IPython\\core\\ultratb.py\", line 1012, in structured_traceback\n",
      "    return VerboseTB.structured_traceback(\n",
      "  File \"c:\\Users\\avern\\AppData\\Local\\Programs\\Python\\Python39\\lib\\site-packages\\IPython\\core\\ultratb.py\", line 865, in structured_traceback\n",
      "    formatted_exception = self.format_exception_as_a_whole(etype, evalue, etb, number_of_lines_of_context,\n",
      "  File \"c:\\Users\\avern\\AppData\\Local\\Programs\\Python\\Python39\\lib\\site-packages\\IPython\\core\\ultratb.py\", line 799, in format_exception_as_a_whole\n",
      "    self.get_records(etb, number_of_lines_of_context, tb_offset) if etb else []\n",
      "  File \"c:\\Users\\avern\\AppData\\Local\\Programs\\Python\\Python39\\lib\\site-packages\\IPython\\core\\ultratb.py\", line 845, in get_records\n",
      "    style = stack_data.style_with_executing_node(style, \"bg:ansiyellow\")\n",
      "  File \"c:\\Users\\avern\\AppData\\Local\\Programs\\Python\\Python39\\lib\\site-packages\\stack_data\\core.py\", line 424, in style_with_executing_node\n",
      "    class NewStyle(style):\n",
      "  File \"c:\\Users\\avern\\AppData\\Local\\Programs\\Python\\Python39\\lib\\site-packages\\pygments\\style.py\", line 91, in __new__\n",
      "    ndef[4] = colorformat(styledef[3:])\n",
      "  File \"c:\\Users\\avern\\AppData\\Local\\Programs\\Python\\Python39\\lib\\site-packages\\pygments\\style.py\", line 58, in colorformat\n",
      "    assert False, \"wrong color format %r\" % text\n",
      "AssertionError: wrong color format 'ansiyellow'\n"
     ]
    }
   ],
   "source": [
    "user_ids = categorization.get_userIds_list()\n",
    "print(len(user_ids))\n",
    "user_ids[:3]"
   ]
  },
  {
   "cell_type": "code",
   "execution_count": null,
   "id": "a075a3da",
   "metadata": {},
   "outputs": [
    {
     "name": "stdout",
     "output_type": "stream",
     "text": [
      "Unexpected exception formatting exception. Falling back to standard exception\n"
     ]
    },
    {
     "name": "stderr",
     "output_type": "stream",
     "text": [
      "Traceback (most recent call last):\n",
      "  File \"c:\\Users\\avern\\AppData\\Local\\Programs\\Python\\Python39\\lib\\site-packages\\IPython\\core\\interactiveshell.py\", line 3369, in run_code\n",
      "    exec(code_obj, self.user_global_ns, self.user_ns)\n",
      "  File \"C:\\Users\\avern\\AppData\\Local\\Temp\\ipykernel_17940\\1896538511.py\", line 2, in <cell line: 2>\n",
      "    categorization.compute_all_scores()\n",
      "NameError: name 'categorization' is not defined\n",
      "\n",
      "During handling of the above exception, another exception occurred:\n",
      "\n",
      "Traceback (most recent call last):\n",
      "  File \"c:\\Users\\avern\\AppData\\Local\\Programs\\Python\\Python39\\lib\\site-packages\\IPython\\core\\interactiveshell.py\", line 1982, in showtraceback\n",
      "    stb = self.InteractiveTB.structured_traceback(\n",
      "  File \"c:\\Users\\avern\\AppData\\Local\\Programs\\Python\\Python39\\lib\\site-packages\\IPython\\core\\ultratb.py\", line 1118, in structured_traceback\n",
      "    return FormattedTB.structured_traceback(\n",
      "  File \"c:\\Users\\avern\\AppData\\Local\\Programs\\Python\\Python39\\lib\\site-packages\\IPython\\core\\ultratb.py\", line 1012, in structured_traceback\n",
      "    return VerboseTB.structured_traceback(\n",
      "  File \"c:\\Users\\avern\\AppData\\Local\\Programs\\Python\\Python39\\lib\\site-packages\\IPython\\core\\ultratb.py\", line 865, in structured_traceback\n",
      "    formatted_exception = self.format_exception_as_a_whole(etype, evalue, etb, number_of_lines_of_context,\n",
      "  File \"c:\\Users\\avern\\AppData\\Local\\Programs\\Python\\Python39\\lib\\site-packages\\IPython\\core\\ultratb.py\", line 799, in format_exception_as_a_whole\n",
      "    self.get_records(etb, number_of_lines_of_context, tb_offset) if etb else []\n",
      "  File \"c:\\Users\\avern\\AppData\\Local\\Programs\\Python\\Python39\\lib\\site-packages\\IPython\\core\\ultratb.py\", line 845, in get_records\n",
      "    style = stack_data.style_with_executing_node(style, \"bg:ansiyellow\")\n",
      "  File \"c:\\Users\\avern\\AppData\\Local\\Programs\\Python\\Python39\\lib\\site-packages\\stack_data\\core.py\", line 424, in style_with_executing_node\n",
      "    class NewStyle(style):\n",
      "  File \"c:\\Users\\avern\\AppData\\Local\\Programs\\Python\\Python39\\lib\\site-packages\\pygments\\style.py\", line 91, in __new__\n",
      "    ndef[4] = colorformat(styledef[3:])\n",
      "  File \"c:\\Users\\avern\\AppData\\Local\\Programs\\Python\\Python39\\lib\\site-packages\\pygments\\style.py\", line 58, in colorformat\n",
      "    assert False, \"wrong color format %r\" % text\n",
      "AssertionError: wrong color format 'ansiyellow'\n"
     ]
    }
   ],
   "source": [
    "t = time.time()\n",
    "categorization.compute_all_scores()\n",
    "print(\"Total time\",time.time()-t)"
   ]
  },
  {
   "cell_type": "code",
   "execution_count": null,
   "id": "f3291f48",
   "metadata": {},
   "outputs": [
    {
     "name": "stdout",
     "output_type": "stream",
     "text": [
      "Unexpected exception formatting exception. Falling back to standard exception\n"
     ]
    },
    {
     "name": "stderr",
     "output_type": "stream",
     "text": [
      "Traceback (most recent call last):\n",
      "  File \"c:\\Users\\avern\\AppData\\Local\\Programs\\Python\\Python39\\lib\\site-packages\\IPython\\core\\interactiveshell.py\", line 3369, in run_code\n",
      "    exec(code_obj, self.user_global_ns, self.user_ns)\n",
      "  File \"C:\\Users\\avern\\AppData\\Local\\Temp\\ipykernel_17940\\299222158.py\", line 3, in <cell line: 3>\n",
      "    r = copy(categorization.users_ddf)\n",
      "NameError: name 'categorization' is not defined\n",
      "\n",
      "During handling of the above exception, another exception occurred:\n",
      "\n",
      "Traceback (most recent call last):\n",
      "  File \"c:\\Users\\avern\\AppData\\Local\\Programs\\Python\\Python39\\lib\\site-packages\\IPython\\core\\interactiveshell.py\", line 1982, in showtraceback\n",
      "    stb = self.InteractiveTB.structured_traceback(\n",
      "  File \"c:\\Users\\avern\\AppData\\Local\\Programs\\Python\\Python39\\lib\\site-packages\\IPython\\core\\ultratb.py\", line 1118, in structured_traceback\n",
      "    return FormattedTB.structured_traceback(\n",
      "  File \"c:\\Users\\avern\\AppData\\Local\\Programs\\Python\\Python39\\lib\\site-packages\\IPython\\core\\ultratb.py\", line 1012, in structured_traceback\n",
      "    return VerboseTB.structured_traceback(\n",
      "  File \"c:\\Users\\avern\\AppData\\Local\\Programs\\Python\\Python39\\lib\\site-packages\\IPython\\core\\ultratb.py\", line 865, in structured_traceback\n",
      "    formatted_exception = self.format_exception_as_a_whole(etype, evalue, etb, number_of_lines_of_context,\n",
      "  File \"c:\\Users\\avern\\AppData\\Local\\Programs\\Python\\Python39\\lib\\site-packages\\IPython\\core\\ultratb.py\", line 799, in format_exception_as_a_whole\n",
      "    self.get_records(etb, number_of_lines_of_context, tb_offset) if etb else []\n",
      "  File \"c:\\Users\\avern\\AppData\\Local\\Programs\\Python\\Python39\\lib\\site-packages\\IPython\\core\\ultratb.py\", line 845, in get_records\n",
      "    style = stack_data.style_with_executing_node(style, \"bg:ansiyellow\")\n",
      "  File \"c:\\Users\\avern\\AppData\\Local\\Programs\\Python\\Python39\\lib\\site-packages\\stack_data\\core.py\", line 424, in style_with_executing_node\n",
      "    class NewStyle(style):\n",
      "  File \"c:\\Users\\avern\\AppData\\Local\\Programs\\Python\\Python39\\lib\\site-packages\\pygments\\style.py\", line 91, in __new__\n",
      "    ndef[4] = colorformat(styledef[3:])\n",
      "  File \"c:\\Users\\avern\\AppData\\Local\\Programs\\Python\\Python39\\lib\\site-packages\\pygments\\style.py\", line 58, in colorformat\n",
      "    assert False, \"wrong color format %r\" % text\n",
      "AssertionError: wrong color format 'ansiyellow'\n"
     ]
    }
   ],
   "source": [
    "from copy import copy\n",
    "\n",
    "r = copy(categorization.users_ddf)\n",
    "r[r[\"uid\"] == \"swungomonkey.698859\"]"
   ]
  },
  {
   "cell_type": "code",
   "execution_count": null,
   "id": "c3cd0b3f",
   "metadata": {},
   "outputs": [
    {
     "name": "stdout",
     "output_type": "stream",
     "text": [
      "Unexpected exception formatting exception. Falling back to standard exception\n"
     ]
    },
    {
     "name": "stderr",
     "output_type": "stream",
     "text": [
      "Traceback (most recent call last):\n",
      "  File \"c:\\Users\\avern\\AppData\\Local\\Programs\\Python\\Python39\\lib\\site-packages\\IPython\\core\\interactiveshell.py\", line 3369, in run_code\n",
      "    exec(code_obj, self.user_global_ns, self.user_ns)\n",
      "  File \"C:\\Users\\avern\\AppData\\Local\\Temp\\ipykernel_17940\\184972716.py\", line 1, in <cell line: 1>\n",
      "    r = copy(categorization.ratings_ddf)\n",
      "NameError: name 'categorization' is not defined\n",
      "\n",
      "During handling of the above exception, another exception occurred:\n",
      "\n",
      "Traceback (most recent call last):\n",
      "  File \"c:\\Users\\avern\\AppData\\Local\\Programs\\Python\\Python39\\lib\\site-packages\\IPython\\core\\interactiveshell.py\", line 1982, in showtraceback\n",
      "    stb = self.InteractiveTB.structured_traceback(\n",
      "  File \"c:\\Users\\avern\\AppData\\Local\\Programs\\Python\\Python39\\lib\\site-packages\\IPython\\core\\ultratb.py\", line 1118, in structured_traceback\n",
      "    return FormattedTB.structured_traceback(\n",
      "  File \"c:\\Users\\avern\\AppData\\Local\\Programs\\Python\\Python39\\lib\\site-packages\\IPython\\core\\ultratb.py\", line 1012, in structured_traceback\n",
      "    return VerboseTB.structured_traceback(\n",
      "  File \"c:\\Users\\avern\\AppData\\Local\\Programs\\Python\\Python39\\lib\\site-packages\\IPython\\core\\ultratb.py\", line 865, in structured_traceback\n",
      "    formatted_exception = self.format_exception_as_a_whole(etype, evalue, etb, number_of_lines_of_context,\n",
      "  File \"c:\\Users\\avern\\AppData\\Local\\Programs\\Python\\Python39\\lib\\site-packages\\IPython\\core\\ultratb.py\", line 799, in format_exception_as_a_whole\n",
      "    self.get_records(etb, number_of_lines_of_context, tb_offset) if etb else []\n",
      "  File \"c:\\Users\\avern\\AppData\\Local\\Programs\\Python\\Python39\\lib\\site-packages\\IPython\\core\\ultratb.py\", line 845, in get_records\n",
      "    style = stack_data.style_with_executing_node(style, \"bg:ansiyellow\")\n",
      "  File \"c:\\Users\\avern\\AppData\\Local\\Programs\\Python\\Python39\\lib\\site-packages\\stack_data\\core.py\", line 424, in style_with_executing_node\n",
      "    class NewStyle(style):\n",
      "  File \"c:\\Users\\avern\\AppData\\Local\\Programs\\Python\\Python39\\lib\\site-packages\\pygments\\style.py\", line 91, in __new__\n",
      "    ndef[4] = colorformat(styledef[3:])\n",
      "  File \"c:\\Users\\avern\\AppData\\Local\\Programs\\Python\\Python39\\lib\\site-packages\\pygments\\style.py\", line 58, in colorformat\n",
      "    assert False, \"wrong color format %r\" % text\n",
      "AssertionError: wrong color format 'ansiyellow'\n"
     ]
    }
   ],
   "source": [
    "r = copy(categorization.ratings_ddf)\n",
    "r[r[\"uid\"] == \"swungomonkey.698859\"]"
   ]
  },
  {
   "cell_type": "code",
   "execution_count": null,
   "id": "f4ca7fee",
   "metadata": {},
   "outputs": [
    {
     "name": "stdout",
     "output_type": "stream",
     "text": [
      "Unexpected exception formatting exception. Falling back to standard exception\n"
     ]
    },
    {
     "name": "stderr",
     "output_type": "stream",
     "text": [
      "Traceback (most recent call last):\n",
      "  File \"c:\\Users\\avern\\AppData\\Local\\Programs\\Python\\Python39\\lib\\site-packages\\IPython\\core\\interactiveshell.py\", line 3369, in run_code\n",
      "    exec(code_obj, self.user_global_ns, self.user_ns)\n",
      "  File \"C:\\Users\\avern\\AppData\\Local\\Temp\\ipykernel_17940\\1935271463.py\", line 4, in <cell line: 4>\n",
      "    r = copy(categorization.users_ddf)\n",
      "NameError: name 'categorization' is not defined\n",
      "\n",
      "During handling of the above exception, another exception occurred:\n",
      "\n",
      "Traceback (most recent call last):\n",
      "  File \"c:\\Users\\avern\\AppData\\Local\\Programs\\Python\\Python39\\lib\\site-packages\\IPython\\core\\interactiveshell.py\", line 1982, in showtraceback\n",
      "    stb = self.InteractiveTB.structured_traceback(\n",
      "  File \"c:\\Users\\avern\\AppData\\Local\\Programs\\Python\\Python39\\lib\\site-packages\\IPython\\core\\ultratb.py\", line 1118, in structured_traceback\n",
      "    return FormattedTB.structured_traceback(\n",
      "  File \"c:\\Users\\avern\\AppData\\Local\\Programs\\Python\\Python39\\lib\\site-packages\\IPython\\core\\ultratb.py\", line 1012, in structured_traceback\n",
      "    return VerboseTB.structured_traceback(\n",
      "  File \"c:\\Users\\avern\\AppData\\Local\\Programs\\Python\\Python39\\lib\\site-packages\\IPython\\core\\ultratb.py\", line 865, in structured_traceback\n",
      "    formatted_exception = self.format_exception_as_a_whole(etype, evalue, etb, number_of_lines_of_context,\n",
      "  File \"c:\\Users\\avern\\AppData\\Local\\Programs\\Python\\Python39\\lib\\site-packages\\IPython\\core\\ultratb.py\", line 799, in format_exception_as_a_whole\n",
      "    self.get_records(etb, number_of_lines_of_context, tb_offset) if etb else []\n",
      "  File \"c:\\Users\\avern\\AppData\\Local\\Programs\\Python\\Python39\\lib\\site-packages\\IPython\\core\\ultratb.py\", line 845, in get_records\n",
      "    style = stack_data.style_with_executing_node(style, \"bg:ansiyellow\")\n",
      "  File \"c:\\Users\\avern\\AppData\\Local\\Programs\\Python\\Python39\\lib\\site-packages\\stack_data\\core.py\", line 424, in style_with_executing_node\n",
      "    class NewStyle(style):\n",
      "  File \"c:\\Users\\avern\\AppData\\Local\\Programs\\Python\\Python39\\lib\\site-packages\\pygments\\style.py\", line 91, in __new__\n",
      "    ndef[4] = colorformat(styledef[3:])\n",
      "  File \"c:\\Users\\avern\\AppData\\Local\\Programs\\Python\\Python39\\lib\\site-packages\\pygments\\style.py\", line 58, in colorformat\n",
      "    assert False, \"wrong color format %r\" % text\n",
      "AssertionError: wrong color format 'ansiyellow'\n"
     ]
    }
   ],
   "source": [
    "from copy import copy\n",
    "uid =  \"nmann08.184925\"\n",
    "\n",
    "r = copy(categorization.users_ddf)\n",
    "r[r[\"uid\"] == uid]"
   ]
  },
  {
   "cell_type": "code",
   "execution_count": null,
   "id": "8c2fbe66",
   "metadata": {},
   "outputs": [
    {
     "name": "stdout",
     "output_type": "stream",
     "text": [
      "Unexpected exception formatting exception. Falling back to standard exception\n"
     ]
    },
    {
     "name": "stderr",
     "output_type": "stream",
     "text": [
      "Traceback (most recent call last):\n",
      "  File \"c:\\Users\\avern\\AppData\\Local\\Programs\\Python\\Python39\\lib\\site-packages\\IPython\\core\\interactiveshell.py\", line 3369, in run_code\n",
      "    exec(code_obj, self.user_global_ns, self.user_ns)\n",
      "  File \"C:\\Users\\avern\\AppData\\Local\\Temp\\ipykernel_17940\\1612596494.py\", line 1, in <cell line: 1>\n",
      "    r = copy(categorization.ratings_ddf)\n",
      "NameError: name 'categorization' is not defined\n",
      "\n",
      "During handling of the above exception, another exception occurred:\n",
      "\n",
      "Traceback (most recent call last):\n",
      "  File \"c:\\Users\\avern\\AppData\\Local\\Programs\\Python\\Python39\\lib\\site-packages\\IPython\\core\\interactiveshell.py\", line 1982, in showtraceback\n",
      "    stb = self.InteractiveTB.structured_traceback(\n",
      "  File \"c:\\Users\\avern\\AppData\\Local\\Programs\\Python\\Python39\\lib\\site-packages\\IPython\\core\\ultratb.py\", line 1118, in structured_traceback\n",
      "    return FormattedTB.structured_traceback(\n",
      "  File \"c:\\Users\\avern\\AppData\\Local\\Programs\\Python\\Python39\\lib\\site-packages\\IPython\\core\\ultratb.py\", line 1012, in structured_traceback\n",
      "    return VerboseTB.structured_traceback(\n",
      "  File \"c:\\Users\\avern\\AppData\\Local\\Programs\\Python\\Python39\\lib\\site-packages\\IPython\\core\\ultratb.py\", line 865, in structured_traceback\n",
      "    formatted_exception = self.format_exception_as_a_whole(etype, evalue, etb, number_of_lines_of_context,\n",
      "  File \"c:\\Users\\avern\\AppData\\Local\\Programs\\Python\\Python39\\lib\\site-packages\\IPython\\core\\ultratb.py\", line 799, in format_exception_as_a_whole\n",
      "    self.get_records(etb, number_of_lines_of_context, tb_offset) if etb else []\n",
      "  File \"c:\\Users\\avern\\AppData\\Local\\Programs\\Python\\Python39\\lib\\site-packages\\IPython\\core\\ultratb.py\", line 845, in get_records\n",
      "    style = stack_data.style_with_executing_node(style, \"bg:ansiyellow\")\n",
      "  File \"c:\\Users\\avern\\AppData\\Local\\Programs\\Python\\Python39\\lib\\site-packages\\stack_data\\core.py\", line 424, in style_with_executing_node\n",
      "    class NewStyle(style):\n",
      "  File \"c:\\Users\\avern\\AppData\\Local\\Programs\\Python\\Python39\\lib\\site-packages\\pygments\\style.py\", line 91, in __new__\n",
      "    ndef[4] = colorformat(styledef[3:])\n",
      "  File \"c:\\Users\\avern\\AppData\\Local\\Programs\\Python\\Python39\\lib\\site-packages\\pygments\\style.py\", line 58, in colorformat\n",
      "    assert False, \"wrong color format %r\" % text\n",
      "AssertionError: wrong color format 'ansiyellow'\n"
     ]
    }
   ],
   "source": [
    "r = copy(categorization.ratings_ddf)\n",
    "r.loc[r[\"uid\"] ==  uid]"
   ]
  },
  {
   "cell_type": "code",
   "execution_count": null,
   "id": "0be8599f",
   "metadata": {},
   "outputs": [
    {
     "name": "stdout",
     "output_type": "stream",
     "text": [
      "Unexpected exception formatting exception. Falling back to standard exception\n"
     ]
    },
    {
     "name": "stderr",
     "output_type": "stream",
     "text": [
      "Traceback (most recent call last):\n",
      "  File \"c:\\Users\\avern\\AppData\\Local\\Programs\\Python\\Python39\\lib\\site-packages\\IPython\\core\\interactiveshell.py\", line 3369, in run_code\n",
      "    exec(code_obj, self.user_global_ns, self.user_ns)\n",
      "  File \"C:\\Users\\avern\\AppData\\Local\\Temp\\ipykernel_17940\\2454203063.py\", line 1, in <cell line: 1>\n",
      "    set_uids = set(categorization.ratings_ddf[\"uid\"])\n",
      "NameError: name 'categorization' is not defined\n",
      "\n",
      "During handling of the above exception, another exception occurred:\n",
      "\n",
      "Traceback (most recent call last):\n",
      "  File \"c:\\Users\\avern\\AppData\\Local\\Programs\\Python\\Python39\\lib\\site-packages\\IPython\\core\\interactiveshell.py\", line 1982, in showtraceback\n",
      "    stb = self.InteractiveTB.structured_traceback(\n",
      "  File \"c:\\Users\\avern\\AppData\\Local\\Programs\\Python\\Python39\\lib\\site-packages\\IPython\\core\\ultratb.py\", line 1118, in structured_traceback\n",
      "    return FormattedTB.structured_traceback(\n",
      "  File \"c:\\Users\\avern\\AppData\\Local\\Programs\\Python\\Python39\\lib\\site-packages\\IPython\\core\\ultratb.py\", line 1012, in structured_traceback\n",
      "    return VerboseTB.structured_traceback(\n",
      "  File \"c:\\Users\\avern\\AppData\\Local\\Programs\\Python\\Python39\\lib\\site-packages\\IPython\\core\\ultratb.py\", line 865, in structured_traceback\n",
      "    formatted_exception = self.format_exception_as_a_whole(etype, evalue, etb, number_of_lines_of_context,\n",
      "  File \"c:\\Users\\avern\\AppData\\Local\\Programs\\Python\\Python39\\lib\\site-packages\\IPython\\core\\ultratb.py\", line 799, in format_exception_as_a_whole\n",
      "    self.get_records(etb, number_of_lines_of_context, tb_offset) if etb else []\n",
      "  File \"c:\\Users\\avern\\AppData\\Local\\Programs\\Python\\Python39\\lib\\site-packages\\IPython\\core\\ultratb.py\", line 845, in get_records\n",
      "    style = stack_data.style_with_executing_node(style, \"bg:ansiyellow\")\n",
      "  File \"c:\\Users\\avern\\AppData\\Local\\Programs\\Python\\Python39\\lib\\site-packages\\stack_data\\core.py\", line 424, in style_with_executing_node\n",
      "    class NewStyle(style):\n",
      "  File \"c:\\Users\\avern\\AppData\\Local\\Programs\\Python\\Python39\\lib\\site-packages\\pygments\\style.py\", line 91, in __new__\n",
      "    ndef[4] = colorformat(styledef[3:])\n",
      "  File \"c:\\Users\\avern\\AppData\\Local\\Programs\\Python\\Python39\\lib\\site-packages\\pygments\\style.py\", line 58, in colorformat\n",
      "    assert False, \"wrong color format %r\" % text\n",
      "AssertionError: wrong color format 'ansiyellow'\n"
     ]
    }
   ],
   "source": [
    "set_uids = set(categorization.ratings_ddf[\"uid\"])\n",
    "len(set_uids)"
   ]
  },
  {
   "cell_type": "code",
   "execution_count": null,
   "id": "e8737484",
   "metadata": {},
   "outputs": [
    {
     "name": "stdout",
     "output_type": "stream",
     "text": [
      "Unexpected exception formatting exception. Falling back to standard exception\n"
     ]
    },
    {
     "name": "stderr",
     "output_type": "stream",
     "text": [
      "Traceback (most recent call last):\n",
      "  File \"c:\\Users\\avern\\AppData\\Local\\Programs\\Python\\Python39\\lib\\site-packages\\IPython\\core\\interactiveshell.py\", line 3369, in run_code\n",
      "    exec(code_obj, self.user_global_ns, self.user_ns)\n",
      "  File \"C:\\Users\\avern\\AppData\\Local\\Temp\\ipykernel_17940\\3965852521.py\", line 1, in <cell line: 1>\n",
      "    users_ddf = copy(categorization.users_ddf)\n",
      "NameError: name 'categorization' is not defined\n",
      "\n",
      "During handling of the above exception, another exception occurred:\n",
      "\n",
      "Traceback (most recent call last):\n",
      "  File \"c:\\Users\\avern\\AppData\\Local\\Programs\\Python\\Python39\\lib\\site-packages\\IPython\\core\\interactiveshell.py\", line 1982, in showtraceback\n",
      "    stb = self.InteractiveTB.structured_traceback(\n",
      "  File \"c:\\Users\\avern\\AppData\\Local\\Programs\\Python\\Python39\\lib\\site-packages\\IPython\\core\\ultratb.py\", line 1118, in structured_traceback\n",
      "    return FormattedTB.structured_traceback(\n",
      "  File \"c:\\Users\\avern\\AppData\\Local\\Programs\\Python\\Python39\\lib\\site-packages\\IPython\\core\\ultratb.py\", line 1012, in structured_traceback\n",
      "    return VerboseTB.structured_traceback(\n",
      "  File \"c:\\Users\\avern\\AppData\\Local\\Programs\\Python\\Python39\\lib\\site-packages\\IPython\\core\\ultratb.py\", line 865, in structured_traceback\n",
      "    formatted_exception = self.format_exception_as_a_whole(etype, evalue, etb, number_of_lines_of_context,\n",
      "  File \"c:\\Users\\avern\\AppData\\Local\\Programs\\Python\\Python39\\lib\\site-packages\\IPython\\core\\ultratb.py\", line 799, in format_exception_as_a_whole\n",
      "    self.get_records(etb, number_of_lines_of_context, tb_offset) if etb else []\n",
      "  File \"c:\\Users\\avern\\AppData\\Local\\Programs\\Python\\Python39\\lib\\site-packages\\IPython\\core\\ultratb.py\", line 845, in get_records\n",
      "    style = stack_data.style_with_executing_node(style, \"bg:ansiyellow\")\n",
      "  File \"c:\\Users\\avern\\AppData\\Local\\Programs\\Python\\Python39\\lib\\site-packages\\stack_data\\core.py\", line 424, in style_with_executing_node\n",
      "    class NewStyle(style):\n",
      "  File \"c:\\Users\\avern\\AppData\\Local\\Programs\\Python\\Python39\\lib\\site-packages\\pygments\\style.py\", line 91, in __new__\n",
      "    ndef[4] = colorformat(styledef[3:])\n",
      "  File \"c:\\Users\\avern\\AppData\\Local\\Programs\\Python\\Python39\\lib\\site-packages\\pygments\\style.py\", line 58, in colorformat\n",
      "    assert False, \"wrong color format %r\" % text\n",
      "AssertionError: wrong color format 'ansiyellow'\n"
     ]
    }
   ],
   "source": [
    "users_ddf = copy(categorization.users_ddf)\n",
    "users_ddf = users_ddf.loc[users_ddf[\"n_ratings\"] > 0]\n",
    "print(len(users_ddf.index))\n",
    "users_ddf.head(5)"
   ]
  },
  {
   "cell_type": "code",
   "execution_count": null,
   "id": "108dd992",
   "metadata": {},
   "outputs": [
    {
     "name": "stdout",
     "output_type": "stream",
     "text": [
      "Unexpected exception formatting exception. Falling back to standard exception\n"
     ]
    },
    {
     "name": "stderr",
     "output_type": "stream",
     "text": [
      "Traceback (most recent call last):\n",
      "  File \"c:\\Users\\avern\\AppData\\Local\\Programs\\Python\\Python39\\lib\\site-packages\\IPython\\core\\interactiveshell.py\", line 3369, in run_code\n",
      "    exec(code_obj, self.user_global_ns, self.user_ns)\n",
      "  File \"C:\\Users\\avern\\AppData\\Local\\Temp\\ipykernel_17940\\3036140498.py\", line 1, in <cell line: 1>\n",
      "    categorization.users_ddf.head(30)\n",
      "NameError: name 'categorization' is not defined\n",
      "\n",
      "During handling of the above exception, another exception occurred:\n",
      "\n",
      "Traceback (most recent call last):\n",
      "  File \"c:\\Users\\avern\\AppData\\Local\\Programs\\Python\\Python39\\lib\\site-packages\\IPython\\core\\interactiveshell.py\", line 1982, in showtraceback\n",
      "    stb = self.InteractiveTB.structured_traceback(\n",
      "  File \"c:\\Users\\avern\\AppData\\Local\\Programs\\Python\\Python39\\lib\\site-packages\\IPython\\core\\ultratb.py\", line 1118, in structured_traceback\n",
      "    return FormattedTB.structured_traceback(\n",
      "  File \"c:\\Users\\avern\\AppData\\Local\\Programs\\Python\\Python39\\lib\\site-packages\\IPython\\core\\ultratb.py\", line 1012, in structured_traceback\n",
      "    return VerboseTB.structured_traceback(\n",
      "  File \"c:\\Users\\avern\\AppData\\Local\\Programs\\Python\\Python39\\lib\\site-packages\\IPython\\core\\ultratb.py\", line 865, in structured_traceback\n",
      "    formatted_exception = self.format_exception_as_a_whole(etype, evalue, etb, number_of_lines_of_context,\n",
      "  File \"c:\\Users\\avern\\AppData\\Local\\Programs\\Python\\Python39\\lib\\site-packages\\IPython\\core\\ultratb.py\", line 799, in format_exception_as_a_whole\n",
      "    self.get_records(etb, number_of_lines_of_context, tb_offset) if etb else []\n",
      "  File \"c:\\Users\\avern\\AppData\\Local\\Programs\\Python\\Python39\\lib\\site-packages\\IPython\\core\\ultratb.py\", line 845, in get_records\n",
      "    style = stack_data.style_with_executing_node(style, \"bg:ansiyellow\")\n",
      "  File \"c:\\Users\\avern\\AppData\\Local\\Programs\\Python\\Python39\\lib\\site-packages\\stack_data\\core.py\", line 424, in style_with_executing_node\n",
      "    class NewStyle(style):\n",
      "  File \"c:\\Users\\avern\\AppData\\Local\\Programs\\Python\\Python39\\lib\\site-packages\\pygments\\style.py\", line 91, in __new__\n",
      "    ndef[4] = colorformat(styledef[3:])\n",
      "  File \"c:\\Users\\avern\\AppData\\Local\\Programs\\Python\\Python39\\lib\\site-packages\\pygments\\style.py\", line 58, in colorformat\n",
      "    assert False, \"wrong color format %r\" % text\n",
      "AssertionError: wrong color format 'ansiyellow'\n"
     ]
    }
   ],
   "source": [
    "categorization.users_ddf.head(30)"
   ]
  },
  {
   "cell_type": "code",
   "execution_count": null,
   "id": "5e2b128e",
   "metadata": {},
   "outputs": [
    {
     "name": "stdout",
     "output_type": "stream",
     "text": [
      "Unexpected exception formatting exception. Falling back to standard exception\n"
     ]
    },
    {
     "name": "stderr",
     "output_type": "stream",
     "text": [
      "Traceback (most recent call last):\n",
      "  File \"c:\\Users\\avern\\AppData\\Local\\Programs\\Python\\Python39\\lib\\site-packages\\IPython\\core\\interactiveshell.py\", line 3369, in run_code\n",
      "    exec(code_obj, self.user_global_ns, self.user_ns)\n",
      "  File \"C:\\Users\\avern\\AppData\\Local\\Temp\\ipykernel_17940\\70581487.py\", line 1, in <cell line: 1>\n",
      "    categorization.beers_ddf.head(20)\n",
      "NameError: name 'categorization' is not defined\n",
      "\n",
      "During handling of the above exception, another exception occurred:\n",
      "\n",
      "Traceback (most recent call last):\n",
      "  File \"c:\\Users\\avern\\AppData\\Local\\Programs\\Python\\Python39\\lib\\site-packages\\IPython\\core\\interactiveshell.py\", line 1982, in showtraceback\n",
      "    stb = self.InteractiveTB.structured_traceback(\n",
      "  File \"c:\\Users\\avern\\AppData\\Local\\Programs\\Python\\Python39\\lib\\site-packages\\IPython\\core\\ultratb.py\", line 1118, in structured_traceback\n",
      "    return FormattedTB.structured_traceback(\n",
      "  File \"c:\\Users\\avern\\AppData\\Local\\Programs\\Python\\Python39\\lib\\site-packages\\IPython\\core\\ultratb.py\", line 1012, in structured_traceback\n",
      "    return VerboseTB.structured_traceback(\n",
      "  File \"c:\\Users\\avern\\AppData\\Local\\Programs\\Python\\Python39\\lib\\site-packages\\IPython\\core\\ultratb.py\", line 865, in structured_traceback\n",
      "    formatted_exception = self.format_exception_as_a_whole(etype, evalue, etb, number_of_lines_of_context,\n",
      "  File \"c:\\Users\\avern\\AppData\\Local\\Programs\\Python\\Python39\\lib\\site-packages\\IPython\\core\\ultratb.py\", line 799, in format_exception_as_a_whole\n",
      "    self.get_records(etb, number_of_lines_of_context, tb_offset) if etb else []\n",
      "  File \"c:\\Users\\avern\\AppData\\Local\\Programs\\Python\\Python39\\lib\\site-packages\\IPython\\core\\ultratb.py\", line 845, in get_records\n",
      "    style = stack_data.style_with_executing_node(style, \"bg:ansiyellow\")\n",
      "  File \"c:\\Users\\avern\\AppData\\Local\\Programs\\Python\\Python39\\lib\\site-packages\\stack_data\\core.py\", line 424, in style_with_executing_node\n",
      "    class NewStyle(style):\n",
      "  File \"c:\\Users\\avern\\AppData\\Local\\Programs\\Python\\Python39\\lib\\site-packages\\pygments\\style.py\", line 91, in __new__\n",
      "    ndef[4] = colorformat(styledef[3:])\n",
      "  File \"c:\\Users\\avern\\AppData\\Local\\Programs\\Python\\Python39\\lib\\site-packages\\pygments\\style.py\", line 58, in colorformat\n",
      "    assert False, \"wrong color format %r\" % text\n",
      "AssertionError: wrong color format 'ansiyellow'\n"
     ]
    }
   ],
   "source": [
    "categorization.beers_ddf.head(20)"
   ]
  },
  {
   "cell_type": "code",
   "execution_count": null,
   "id": "97799697",
   "metadata": {},
   "outputs": [],
   "source": []
  },
  {
   "cell_type": "code",
   "execution_count": null,
   "id": "bcbb5663",
   "metadata": {},
   "outputs": [],
   "source": []
  },
  {
   "cell_type": "code",
   "execution_count": null,
   "id": "f7e50940",
   "metadata": {},
   "outputs": [
    {
     "name": "stdout",
     "output_type": "stream",
     "text": [
      "Unexpected exception formatting exception. Falling back to standard exception\n"
     ]
    },
    {
     "name": "stderr",
     "output_type": "stream",
     "text": [
      "Traceback (most recent call last):\n",
      "  File \"c:\\Users\\avern\\AppData\\Local\\Programs\\Python\\Python39\\lib\\site-packages\\IPython\\core\\interactiveshell.py\", line 3369, in run_code\n",
      "    exec(code_obj, self.user_global_ns, self.user_ns)\n",
      "  File \"C:\\Users\\avern\\AppData\\Local\\Temp\\ipykernel_17940\\522405502.py\", line 1, in <cell line: 1>\n",
      "    adventurer_scores = categorization.get_adventurer_score()\n",
      "NameError: name 'categorization' is not defined\n",
      "\n",
      "During handling of the above exception, another exception occurred:\n",
      "\n",
      "Traceback (most recent call last):\n",
      "  File \"c:\\Users\\avern\\AppData\\Local\\Programs\\Python\\Python39\\lib\\site-packages\\IPython\\core\\interactiveshell.py\", line 1982, in showtraceback\n",
      "    stb = self.InteractiveTB.structured_traceback(\n",
      "  File \"c:\\Users\\avern\\AppData\\Local\\Programs\\Python\\Python39\\lib\\site-packages\\IPython\\core\\ultratb.py\", line 1118, in structured_traceback\n",
      "    return FormattedTB.structured_traceback(\n",
      "  File \"c:\\Users\\avern\\AppData\\Local\\Programs\\Python\\Python39\\lib\\site-packages\\IPython\\core\\ultratb.py\", line 1012, in structured_traceback\n",
      "    return VerboseTB.structured_traceback(\n",
      "  File \"c:\\Users\\avern\\AppData\\Local\\Programs\\Python\\Python39\\lib\\site-packages\\IPython\\core\\ultratb.py\", line 865, in structured_traceback\n",
      "    formatted_exception = self.format_exception_as_a_whole(etype, evalue, etb, number_of_lines_of_context,\n",
      "  File \"c:\\Users\\avern\\AppData\\Local\\Programs\\Python\\Python39\\lib\\site-packages\\IPython\\core\\ultratb.py\", line 799, in format_exception_as_a_whole\n",
      "    self.get_records(etb, number_of_lines_of_context, tb_offset) if etb else []\n",
      "  File \"c:\\Users\\avern\\AppData\\Local\\Programs\\Python\\Python39\\lib\\site-packages\\IPython\\core\\ultratb.py\", line 845, in get_records\n",
      "    style = stack_data.style_with_executing_node(style, \"bg:ansiyellow\")\n",
      "  File \"c:\\Users\\avern\\AppData\\Local\\Programs\\Python\\Python39\\lib\\site-packages\\stack_data\\core.py\", line 424, in style_with_executing_node\n",
      "    class NewStyle(style):\n",
      "  File \"c:\\Users\\avern\\AppData\\Local\\Programs\\Python\\Python39\\lib\\site-packages\\pygments\\style.py\", line 91, in __new__\n",
      "    ndef[4] = colorformat(styledef[3:])\n",
      "  File \"c:\\Users\\avern\\AppData\\Local\\Programs\\Python\\Python39\\lib\\site-packages\\pygments\\style.py\", line 58, in colorformat\n",
      "    assert False, \"wrong color format %r\" % text\n",
      "AssertionError: wrong color format 'ansiyellow'\n"
     ]
    }
   ],
   "source": [
    "adventurer_scores = categorization.get_adventurer_score()\n",
    "print(adventurer_scores)\n",
    "categorization.users_ddf"
   ]
  },
  {
   "cell_type": "code",
   "execution_count": null,
   "id": "9f48b525",
   "metadata": {},
   "outputs": [],
   "source": []
  },
  {
   "cell_type": "code",
   "execution_count": null,
   "id": "e76d8d16",
   "metadata": {},
   "outputs": [
    {
     "name": "stdout",
     "output_type": "stream",
     "text": [
      "Unexpected exception formatting exception. Falling back to standard exception\n"
     ]
    },
    {
     "name": "stderr",
     "output_type": "stream",
     "text": [
      "Traceback (most recent call last):\n",
      "  File \"c:\\Users\\avern\\AppData\\Local\\Programs\\Python\\Python39\\lib\\site-packages\\IPython\\core\\interactiveshell.py\", line 3369, in run_code\n",
      "    exec(code_obj, self.user_global_ns, self.user_ns)\n",
      "  File \"C:\\Users\\avern\\AppData\\Local\\Temp\\ipykernel_17940\\1103767120.py\", line 1, in <cell line: 1>\n",
      "    explorer_scores = categorization.get_explorer_score_for_all_users()\n",
      "NameError: name 'categorization' is not defined\n",
      "\n",
      "During handling of the above exception, another exception occurred:\n",
      "\n",
      "Traceback (most recent call last):\n",
      "  File \"c:\\Users\\avern\\AppData\\Local\\Programs\\Python\\Python39\\lib\\site-packages\\IPython\\core\\interactiveshell.py\", line 1982, in showtraceback\n",
      "    stb = self.InteractiveTB.structured_traceback(\n",
      "  File \"c:\\Users\\avern\\AppData\\Local\\Programs\\Python\\Python39\\lib\\site-packages\\IPython\\core\\ultratb.py\", line 1118, in structured_traceback\n",
      "    return FormattedTB.structured_traceback(\n",
      "  File \"c:\\Users\\avern\\AppData\\Local\\Programs\\Python\\Python39\\lib\\site-packages\\IPython\\core\\ultratb.py\", line 1012, in structured_traceback\n",
      "    return VerboseTB.structured_traceback(\n",
      "  File \"c:\\Users\\avern\\AppData\\Local\\Programs\\Python\\Python39\\lib\\site-packages\\IPython\\core\\ultratb.py\", line 865, in structured_traceback\n",
      "    formatted_exception = self.format_exception_as_a_whole(etype, evalue, etb, number_of_lines_of_context,\n",
      "  File \"c:\\Users\\avern\\AppData\\Local\\Programs\\Python\\Python39\\lib\\site-packages\\IPython\\core\\ultratb.py\", line 799, in format_exception_as_a_whole\n",
      "    self.get_records(etb, number_of_lines_of_context, tb_offset) if etb else []\n",
      "  File \"c:\\Users\\avern\\AppData\\Local\\Programs\\Python\\Python39\\lib\\site-packages\\IPython\\core\\ultratb.py\", line 845, in get_records\n",
      "    style = stack_data.style_with_executing_node(style, \"bg:ansiyellow\")\n",
      "  File \"c:\\Users\\avern\\AppData\\Local\\Programs\\Python\\Python39\\lib\\site-packages\\stack_data\\core.py\", line 424, in style_with_executing_node\n",
      "    class NewStyle(style):\n",
      "  File \"c:\\Users\\avern\\AppData\\Local\\Programs\\Python\\Python39\\lib\\site-packages\\pygments\\style.py\", line 91, in __new__\n",
      "    ndef[4] = colorformat(styledef[3:])\n",
      "  File \"c:\\Users\\avern\\AppData\\Local\\Programs\\Python\\Python39\\lib\\site-packages\\pygments\\style.py\", line 58, in colorformat\n",
      "    assert False, \"wrong color format %r\" % text\n",
      "AssertionError: wrong color format 'ansiyellow'\n"
     ]
    }
   ],
   "source": [
    "explorer_scores = categorization.get_explorer_score_for_all_users()\n",
    "print(explorer_scoresorer_scores)\n",
    "categorization.users_ddf"
   ]
  },
  {
   "cell_type": "code",
   "execution_count": null,
   "id": "43f42e95",
   "metadata": {},
   "outputs": [],
   "source": []
  },
  {
   "cell_type": "code",
   "execution_count": null,
   "id": "e09ffb1b",
   "metadata": {},
   "outputs": [],
   "source": []
  },
  {
   "cell_type": "code",
   "execution_count": null,
   "id": "69a08e17",
   "metadata": {},
   "outputs": [],
   "source": []
  },
  {
   "cell_type": "code",
   "execution_count": null,
   "id": "69195de3",
   "metadata": {},
   "outputs": [],
   "source": []
  },
  {
   "cell_type": "code",
   "execution_count": null,
   "id": "4ec2e6c3",
   "metadata": {},
   "outputs": [],
   "source": []
  },
  {
   "cell_type": "code",
   "execution_count": null,
   "id": "60f8df72",
   "metadata": {},
   "outputs": [],
   "source": []
  },
  {
   "cell_type": "code",
   "execution_count": null,
   "id": "ee73e97a",
   "metadata": {},
   "outputs": [],
   "source": []
  }
 ],
 "metadata": {
  "kernelspec": {
   "display_name": "Python 3 (ipykernel)",
   "language": "python",
   "name": "python3"
  },
  "language_info": {
   "codemirror_mode": {
    "name": "ipython",
    "version": 3
   },
   "file_extension": ".py",
   "mimetype": "text/x-python",
   "name": "python",
   "nbconvert_exporter": "python",
   "pygments_lexer": "ipython3",
   "version": "3.9.10"
  },
  "vscode": {
   "interpreter": {
    "hash": "a6b17080f85ea43cbd537a9c7f7efa989c8a5a37822a332847af53db68a78ddf"
   }
  }
 },
 "nbformat": 4,
 "nbformat_minor": 5
}
